Internal Server Error: /catalogue/
Traceback (most recent call last):
  File "c:\Users\fady\Documents\django projects\part-shop\oscar\Lib\site-packages\django\core\handlers\exception.py", line 55, in inner
    response = get_response(request)
               ^^^^^^^^^^^^^^^^^^^^^
  File "c:\Users\fady\Documents\django projects\part-shop\oscar\Lib\site-packages\django\core\handlers\base.py", line 197, in _get_response
    response = wrapped_callback(request, *callback_args, **callback_kwargs)
               ^^^^^^^^^^^^^^^^^^^^^^^^^^^^^^^^^^^^^^^^^^^^^^^^^^^^^^^^^^^^
  File "c:\Users\fady\Documents\django projects\part-shop\oscar\Lib\site-packages\django\views\generic\base.py", line 104, in view
    return self.dispatch(request, *args, **kwargs)
           ^^^^^^^^^^^^^^^^^^^^^^^^^^^^^^^^^^^^^^^
  File "c:\Users\fady\Documents\django projects\part-shop\oscar\Lib\site-packages\django\views\generic\base.py", line 143, in dispatch
    return handler(request, *args, **kwargs)
           ^^^^^^^^^^^^^^^^^^^^^^^^^^^^^^^^^
  File "c:\Users\fady\Documents\django projects\part-shop\oscar\Lib\site-packages\oscar\apps\search\views\catalogue.py", line 36, in get
    return super().get(request, *args, **kwargs)
           ^^^^^^^^^^^^^^^^^^^^^^^^^^^^^^^^^^^^^
  File "c:\Users\fady\Documents\django projects\part-shop\oscar\Lib\site-packages\haystack\generic_views.py", line 130, in get
    return self.form_valid(form)
           ^^^^^^^^^^^^^^^^^^^^^
  File "c:\Users\fady\Documents\django projects\part-shop\oscar\Lib\site-packages\haystack\generic_views.py", line 77, in form_valid
    context = self.get_context_data(
              ^^^^^^^^^^^^^^^^^^^^^^
  File "c:\Users\fady\Documents\django projects\part-shop\oscar\Lib\site-packages\oscar\apps\search\views\catalogue.py", line 43, in get_context_data
    ctx = super().get_context_data(*args, **kwargs)
          ^^^^^^^^^^^^^^^^^^^^^^^^^^^^^^^^^^^^^^^^^
  File "c:\Users\fady\Documents\django projects\part-shop\oscar\Lib\site-packages\oscar\apps\search\views\base.py", line 19, in get_context_data
    context = super().get_context_data(*args, **kwargs)
              ^^^^^^^^^^^^^^^^^^^^^^^^^^^^^^^^^^^^^^^^^
  File "c:\Users\fady\Documents\django projects\part-shop\oscar\Lib\site-packages\haystack\generic_views.py", line 104, in get_context_data
    context.update({"facets": self.queryset.facet_counts()})
                              ^^^^^^^^^^^^^^^^^^^^^^^^^^
AttributeError: 'ProductQuerySet' object has no attribute 'facet_counts'
"GET /catalogue/ HTTP/1.1" 500 119792
Internal Server Error: /catalogue/
Traceback (most recent call last):
  File "c:\Users\fady\Documents\django projects\part-shop\oscar\Lib\site-packages\django\core\handlers\exception.py", line 55, in inner
    response = get_response(request)
               ^^^^^^^^^^^^^^^^^^^^^
  File "c:\Users\fady\Documents\django projects\part-shop\oscar\Lib\site-packages\django\core\handlers\base.py", line 197, in _get_response
    response = wrapped_callback(request, *callback_args, **callback_kwargs)
               ^^^^^^^^^^^^^^^^^^^^^^^^^^^^^^^^^^^^^^^^^^^^^^^^^^^^^^^^^^^^
  File "c:\Users\fady\Documents\django projects\part-shop\oscar\Lib\site-packages\django\views\generic\base.py", line 104, in view
    return self.dispatch(request, *args, **kwargs)
           ^^^^^^^^^^^^^^^^^^^^^^^^^^^^^^^^^^^^^^^
  File "c:\Users\fady\Documents\django projects\part-shop\oscar\Lib\site-packages\django\views\generic\base.py", line 143, in dispatch
    return handler(request, *args, **kwargs)
           ^^^^^^^^^^^^^^^^^^^^^^^^^^^^^^^^^
  File "c:\Users\fady\Documents\django projects\part-shop\oscar\Lib\site-packages\oscar\apps\search\views\catalogue.py", line 36, in get
    return super().get(request, *args, **kwargs)
           ^^^^^^^^^^^^^^^^^^^^^^^^^^^^^^^^^^^^^
  File "c:\Users\fady\Documents\django projects\part-shop\oscar\Lib\site-packages\django\views\generic\base.py", line 226, in get
    context = self.get_context_data(**kwargs)
              ^^^^^^^^^^^^^^^^^^^^^^^^^^^^^^^
  File "c:\Users\fady\Documents\django projects\part-shop\oscar\Lib\site-packages\oscar\apps\search\views\catalogue.py", line 62, in get_context_data
    ctx["products"] = self.get_queryset()  # Ensure products are added
                      ^^^^^^^^^^^^^^^^^
AttributeError: 'CatalogueView' object has no attribute 'get_queryset'
"GET /catalogue/ HTTP/1.1" 500 105672
Internal Server Error: /catalogue/
Traceback (most recent call last):
  File "c:\Users\fady\Documents\django projects\part-shop\oscar\Lib\site-packages\django\core\handlers\exception.py", line 55, in inner
    response = get_response(request)
               ^^^^^^^^^^^^^^^^^^^^^
  File "c:\Users\fady\Documents\django projects\part-shop\oscar\Lib\site-packages\django\core\handlers\base.py", line 197, in _get_response
    response = wrapped_callback(request, *callback_args, **callback_kwargs)
               ^^^^^^^^^^^^^^^^^^^^^^^^^^^^^^^^^^^^^^^^^^^^^^^^^^^^^^^^^^^^
  File "c:\Users\fady\Documents\django projects\part-shop\oscar\Lib\site-packages\django\views\generic\base.py", line 104, in view
    return self.dispatch(request, *args, **kwargs)
           ^^^^^^^^^^^^^^^^^^^^^^^^^^^^^^^^^^^^^^^
  File "c:\Users\fady\Documents\django projects\part-shop\oscar\Lib\site-packages\django\views\generic\base.py", line 143, in dispatch
    return handler(request, *args, **kwargs)
           ^^^^^^^^^^^^^^^^^^^^^^^^^^^^^^^^^
  File "c:\Users\fady\Documents\django projects\part-shop\oscar\Lib\site-packages\oscar\apps\search\views\catalogue.py", line 38, in get
    return super().get(request, *args, **kwargs)
           ^^^^^^^^^^^^^^^^^^^^^^^^^^^^^^^^^^^^^
  File "c:\Users\fady\Documents\django projects\part-shop\oscar\Lib\site-packages\django\views\generic\base.py", line 226, in get
    context = self.get_context_data(**kwargs)
              ^^^^^^^^^^^^^^^^^^^^^^^^^^^^^^^
  File "c:\Users\fady\Documents\django projects\part-shop\oscar\Lib\site-packages\oscar\apps\search\views\catalogue.py", line 64, in get_context_data
    ctx["products"] = self.get_queryset()  # Ensure products are added
                      ^^^^^^^^^^^^^^^^^
AttributeError: 'CatalogueView' object has no attribute 'get_queryset'
"GET /catalogue/ HTTP/1.1" 500 105672
Internal Server Error: /catalogue/
Traceback (most recent call last):
  File "c:\Users\fady\Documents\django projects\part-shop\oscar\Lib\site-packages\django\core\handlers\exception.py", line 55, in inner
    response = get_response(request)
               ^^^^^^^^^^^^^^^^^^^^^
  File "c:\Users\fady\Documents\django projects\part-shop\oscar\Lib\site-packages\django\core\handlers\base.py", line 197, in _get_response
    response = wrapped_callback(request, *callback_args, **callback_kwargs)
               ^^^^^^^^^^^^^^^^^^^^^^^^^^^^^^^^^^^^^^^^^^^^^^^^^^^^^^^^^^^^
  File "c:\Users\fady\Documents\django projects\part-shop\oscar\Lib\site-packages\django\views\generic\base.py", line 104, in view
    return self.dispatch(request, *args, **kwargs)
           ^^^^^^^^^^^^^^^^^^^^^^^^^^^^^^^^^^^^^^^
  File "c:\Users\fady\Documents\django projects\part-shop\oscar\Lib\site-packages\django\views\generic\base.py", line 143, in dispatch
    return handler(request, *args, **kwargs)
           ^^^^^^^^^^^^^^^^^^^^^^^^^^^^^^^^^
  File "c:\Users\fady\Documents\django projects\part-shop\oscar\Lib\site-packages\oscar\apps\search\views\catalogue.py", line 38, in get
    return super().get(request, *args, **kwargs)
           ^^^^^^^^^^^^^^^^^^^^^^^^^^^^^^^^^^^^^
  File "c:\Users\fady\Documents\django projects\part-shop\oscar\Lib\site-packages\django\views\generic\base.py", line 226, in get
    context = self.get_context_data(**kwargs)
              ^^^^^^^^^^^^^^^^^^^^^^^^^^^^^^^
  File "c:\Users\fady\Documents\django projects\part-shop\oscar\Lib\site-packages\oscar\apps\search\views\catalogue.py", line 64, in get_context_data
    ctx["products"] = self.get_queryset()  # Ensure products are added
                      ^^^^^^^^^^^^^^^^^
AttributeError: 'CatalogueView' object has no attribute 'get_queryset'
"GET /catalogue/ HTTP/1.1" 500 105672
Internal Server Error: /catalogue/
Traceback (most recent call last):
  File "c:\Users\fady\Documents\django projects\part-shop\oscar\Lib\site-packages\django\template\library.py", line 350, in parse_bits
    unhandled_params.pop(0)
IndexError: pop from empty list

During handling of the above exception, another exception occurred:

Traceback (most recent call last):
  File "c:\Users\fady\Documents\django projects\part-shop\oscar\Lib\site-packages\django\core\handlers\exception.py", line 55, in inner
    response = get_response(request)
               ^^^^^^^^^^^^^^^^^^^^^
  File "c:\Users\fady\Documents\django projects\part-shop\oscar\Lib\site-packages\django\core\handlers\base.py", line 220, in _get_response
    response = response.render()
               ^^^^^^^^^^^^^^^^^
  File "c:\Users\fady\Documents\django projects\part-shop\oscar\Lib\site-packages\django\template\response.py", line 114, in render
    self.content = self.rendered_content
                   ^^^^^^^^^^^^^^^^^^^^^
  File "c:\Users\fady\Documents\django projects\part-shop\oscar\Lib\site-packages\django\template\response.py", line 90, in rendered_content
    template = self.resolve_template(self.template_name)
               ^^^^^^^^^^^^^^^^^^^^^^^^^^^^^^^^^^^^^^^^^
  File "c:\Users\fady\Documents\django projects\part-shop\oscar\Lib\site-packages\django\template\response.py", line 72, in resolve_template
    return select_template(template, using=self.using)
           ^^^^^^^^^^^^^^^^^^^^^^^^^^^^^^^^^^^^^^^^^^^
  File "c:\Users\fady\Documents\django projects\part-shop\oscar\Lib\site-packages\django\template\loader.py", line 42, in select_template
    return engine.get_template(template_name)
           ^^^^^^^^^^^^^^^^^^^^^^^^^^^^^^^^^^
  File "c:\Users\fady\Documents\django projects\part-shop\oscar\Lib\site-packages\django\template\backends\django.py", line 33, in get_template
    return Template(self.engine.get_template(template_name), self)
                    ^^^^^^^^^^^^^^^^^^^^^^^^^^^^^^^^^^^^^^^
  File "c:\Users\fady\Documents\django projects\part-shop\oscar\Lib\site-packages\django\template\engine.py", line 175, in get_template
    template, origin = self.find_template(template_name)
                       ^^^^^^^^^^^^^^^^^^^^^^^^^^^^^^^^^
  File "c:\Users\fady\Documents\django projects\part-shop\oscar\Lib\site-packages\django\template\engine.py", line 157, in find_template
    template = loader.get_template(name, skip=skip)
               ^^^^^^^^^^^^^^^^^^^^^^^^^^^^^^^^^^^^
  File "c:\Users\fady\Documents\django projects\part-shop\oscar\Lib\site-packages\django\template\loaders\cached.py", line 57, in get_template
    template = super().get_template(template_name, skip)
               ^^^^^^^^^^^^^^^^^^^^^^^^^^^^^^^^^^^^^^^^^
  File "c:\Users\fady\Documents\django projects\part-shop\oscar\Lib\site-packages\django\template\loaders\base.py", line 28, in get_template
    return Template(
           ^^^^^^^^^
  File "c:\Users\fady\Documents\django projects\part-shop\oscar\Lib\site-packages\django\template\base.py", line 154, in __init__
    self.nodelist = self.compile_nodelist()
                    ^^^^^^^^^^^^^^^^^^^^^^^
  File "c:\Users\fady\Documents\django projects\part-shop\oscar\Lib\site-packages\django\template\base.py", line 200, in compile_nodelist
    return parser.parse()
           ^^^^^^^^^^^^^^
  File "c:\Users\fady\Documents\django projects\part-shop\oscar\Lib\site-packages\django\template\base.py", line 513, in parse
    raise self.error(token, e)
  File "c:\Users\fady\Documents\django projects\part-shop\oscar\Lib\site-packages\django\template\base.py", line 511, in parse
    compiled_result = compile_func(self, token)
                      ^^^^^^^^^^^^^^^^^^^^^^^^^
  File "c:\Users\fady\Documents\django projects\part-shop\oscar\Lib\site-packages\django\template\loader_tags.py", line 293, in do_extends
    nodelist = parser.parse()
               ^^^^^^^^^^^^^^
  File "c:\Users\fady\Documents\django projects\part-shop\oscar\Lib\site-packages\django\template\base.py", line 513, in parse
    raise self.error(token, e)
  File "c:\Users\fady\Documents\django projects\part-shop\oscar\Lib\site-packages\django\template\base.py", line 511, in parse
    compiled_result = compile_func(self, token)
                      ^^^^^^^^^^^^^^^^^^^^^^^^^
  File "c:\Users\fady\Documents\django projects\part-shop\oscar\Lib\site-packages\django\template\loader_tags.py", line 232, in do_block
    nodelist = parser.parse(("endblock",))
               ^^^^^^^^^^^^^^^^^^^^^^^^^^^
  File "c:\Users\fady\Documents\django projects\part-shop\oscar\Lib\site-packages\django\template\base.py", line 513, in parse
    raise self.error(token, e)
  File "c:\Users\fady\Documents\django projects\part-shop\oscar\Lib\site-packages\django\template\base.py", line 511, in parse
    compiled_result = compile_func(self, token)
                      ^^^^^^^^^^^^^^^^^^^^^^^^^
  File "c:\Users\fady\Documents\django projects\part-shop\oscar\Lib\site-packages\django\template\defaulttags.py", line 853, in do_for
    nodelist_loop = parser.parse(
                    ^^^^^^^^^^^^^
  File "c:\Users\fady\Documents\django projects\part-shop\oscar\Lib\site-packages\django\template\base.py", line 513, in parse
    raise self.error(token, e)
  File "c:\Users\fady\Documents\django projects\part-shop\oscar\Lib\site-packages\django\template\base.py", line 511, in parse
    compiled_result = compile_func(self, token)
                      ^^^^^^^^^^^^^^^^^^^^^^^^^
  File "c:\Users\fady\Documents\django projects\part-shop\oscar\Lib\site-packages\django\template\library.py", line 130, in compile_func
    args, kwargs = parse_bits(
                   ^^^^^^^^^^^
  File "c:\Users\fady\Documents\django projects\part-shop\oscar\Lib\site-packages\django\template\library.py", line 353, in parse_bits
    raise TemplateSyntaxError(
django.template.exceptions.TemplateSyntaxError: 'render_product' received too many positional arguments
"GET /catalogue/ HTTP/1.1" 500 253845
