Internal Server Error: /catalogue/
Traceback (most recent call last):
  File "c:\Users\fady\Documents\django projects\part-shop\oscar\Lib\site-packages\django\core\handlers\exception.py", line 55, in inner
    response = get_response(request)
               ^^^^^^^^^^^^^^^^^^^^^
  File "c:\Users\fady\Documents\django projects\part-shop\oscar\Lib\site-packages\django\core\handlers\base.py", line 197, in _get_response
    response = wrapped_callback(request, *callback_args, **callback_kwargs)
               ^^^^^^^^^^^^^^^^^^^^^^^^^^^^^^^^^^^^^^^^^^^^^^^^^^^^^^^^^^^^
  File "c:\Users\fady\Documents\django projects\part-shop\oscar\Lib\site-packages\django\views\generic\base.py", line 104, in view
    return self.dispatch(request, *args, **kwargs)
           ^^^^^^^^^^^^^^^^^^^^^^^^^^^^^^^^^^^^^^^
  File "c:\Users\fady\Documents\django projects\part-shop\oscar\Lib\site-packages\django\views\generic\base.py", line 143, in dispatch
    return handler(request, *args, **kwargs)
           ^^^^^^^^^^^^^^^^^^^^^^^^^^^^^^^^^
  File "c:\Users\fady\Documents\django projects\part-shop\oscar\Lib\site-packages\oscar\apps\search\views\catalogue.py", line 36, in get
    return super().get(request, *args, **kwargs)
           ^^^^^^^^^^^^^^^^^^^^^^^^^^^^^^^^^^^^^
  File "c:\Users\fady\Documents\django projects\part-shop\oscar\Lib\site-packages\haystack\generic_views.py", line 130, in get
    return self.form_valid(form)
           ^^^^^^^^^^^^^^^^^^^^^
  File "c:\Users\fady\Documents\django projects\part-shop\oscar\Lib\site-packages\haystack\generic_views.py", line 77, in form_valid
    context = self.get_context_data(
              ^^^^^^^^^^^^^^^^^^^^^^
  File "c:\Users\fady\Documents\django projects\part-shop\oscar\Lib\site-packages\oscar\apps\search\views\catalogue.py", line 43, in get_context_data
    ctx = super().get_context_data(*args, **kwargs)
          ^^^^^^^^^^^^^^^^^^^^^^^^^^^^^^^^^^^^^^^^^
  File "c:\Users\fady\Documents\django projects\part-shop\oscar\Lib\site-packages\oscar\apps\search\views\base.py", line 19, in get_context_data
    context = super().get_context_data(*args, **kwargs)
              ^^^^^^^^^^^^^^^^^^^^^^^^^^^^^^^^^^^^^^^^^
  File "c:\Users\fady\Documents\django projects\part-shop\oscar\Lib\site-packages\haystack\generic_views.py", line 104, in get_context_data
    context.update({"facets": self.queryset.facet_counts()})
                              ^^^^^^^^^^^^^^^^^^^^^^^^^^
AttributeError: 'ProductQuerySet' object has no attribute 'facet_counts'
"GET /catalogue/ HTTP/1.1" 500 119792
